Workbook

Sheet Executive Summary
A1: GeoQueryBench — Combined Group Error Report
A2: Combined from Ziyue, Sarwesh, Chaitanya, Dilani and Thomas | 349 unique allocated query reviews
A4: Executive measure | B4: Result | D4: Reviewer | E4: Assigned | F4: Formal Errors | G4: Notes | H4: Pass | I4: Pass with Note | J4: Fail | K4: Manual Review | L4: Match | M4: Mismatch | N4: Valid Refusal | O4: Reference-only
A5: Combined query rows | B5: =COUNTA('All Query Reviews'!B2:B350) -> 349 | D5: Ziyue | E5: =COUNTIF('All Query Reviews'!$A$2:$A$350,D5) -> 69 | F5: =COUNTIF('Error Register'!$A$2:$A$40,D5) -> 23 | G5: =COUNTIF('Review Notes'!$A$2:$A$59,D5) -> 27 | H5: =COUNTIFS('All Query Reviews'!$A$2:$A$350,D5,'All Query Reviews'!$AG$2:$AG$350,"Pass") -> 19 | I5: =COUNTIFS('All Query Reviews'!$A$2:$A$350,D5,'All Query Reviews'!$AG$2:$AG$350,"Pass with note") -> 27 | J5: =COUNTIFS('All Query Reviews'!$A$2:$A$350,D5,'All Query Reviews'!$AG$2:$AG$350,"Fail") -> 23 | K5: =COUNTIFS('All Query Reviews'!$A$2:$A$350,D5,'All Query Reviews'!$AG$2:$AG$350,"Requires manual semantic review") -> 0 | L5: =COUNTIFS('All Query Reviews'!$A$2:$A$350,D5,'All Query Reviews'!$AG$2:$AG$350,"Match") -> 0 | M5: =COUNTIFS('All Query Reviews'!$A$2:$A$350,D5,'All Query Reviews'!$AG$2:$AG$350,"Mismatch") -> 0 | N5: =COUNTIFS('All Query Reviews'!$A$2:$A$350,D5,'All Query Reviews'!$AG$2:$AG$350,"Valid refusal") -> 0 | O5: =COUNTIFS('All Query Reviews'!$A$2:$A$350,D5,'All Query Reviews'!$AG$2:$AG$350,"Reference-only") -> 0
A6: Formal error-register entries | B6: =COUNTA('Error Register'!B2:B40) -> 39 | D6: Sarwesh | E6: =COUNTIF('All Query Reviews'!$A$2:$A$350,D6) -> 70 | F6: =COUNTIF('Error Register'!$A$2:$A$40,D6) -> 4 | G6: =COUNTIF('Review Notes'!$A$2:$A$59,D6) -> 5 | H6: =COUNTIFS('All Query Reviews'!$A$2:$A$350,D6,'All Query Reviews'!$AG$2:$AG$350,"Pass") -> 60 | I6: =COUNTIFS('All Query Reviews'!$A$2:$A$350,D6,'All Query Reviews'!$AG$2:$AG$350,"Pass with note") -> 5 | J6: =COUNTIFS('All Query Reviews'!$A$2:$A$350,D6,'All Query Reviews'!$AG$2:$AG$350,"Fail") -> 4 | K6: =COUNTIFS('All Query Reviews'!$A$2:$A$350,D6,'All Query Reviews'!$AG$2:$AG$350,"Requires manual semantic review") -> 1 | L6: =COUNTIFS('All Query Reviews'!$A$2:$A$350,D6,'All Query Reviews'!$AG$2:$AG$350,"Match") -> 0 | M6: =COUNTIFS('All Query Reviews'!$A$2:$A$350,D6,'All Query Reviews'!$AG$2:$AG$350,"Mismatch") -> 0 | N6: =COUNTIFS('All Query Reviews'!$A$2:$A$350,D6,'All Query Reviews'!$AG$2:$AG$350,"Valid refusal") -> 0 | O6: =COUNTIFS('All Query Reviews'!$A$2:$A$350,D6,'All Query Reviews'!$AG$2:$AG$350,"Reference-only") -> 0
A7: Review-note entries | B7: =COUNTA('Review Notes'!B2:B59) -> 58 | D7: Chaitanya | E7: =COUNTIF('All Query Reviews'!$A$2:$A$350,D7) -> 70 | F7: =COUNTIF('Error Register'!$A$2:$A$40,D7) -> 2 | G7: =COUNTIF('Review Notes'!$A$2:$A$59,D7) -> 5 | H7: =COUNTIFS('All Query Reviews'!$A$2:$A$350,D7,'All Query Reviews'!$AG$2:$AG$350,"Pass") -> 0 | I7: =COUNTIFS('All Query Reviews'!$A$2:$A$350,D7,'All Query Reviews'!$AG$2:$AG$350,"Pass with note") -> 0 | J7: =COUNTIFS('All Query Reviews'!$A$2:$A$350,D7,'All Query Reviews'!$AG$2:$AG$350,"Fail") -> 0 | K7: =COUNTIFS('All Query Reviews'!$A$2:$A$350,D7,'All Query Reviews'!$AG$2:$AG$350,"Requires manual semantic review") -> 0 | L7: =COUNTIFS('All Query Reviews'!$A$2:$A$350,D7,'All Query Reviews'!$AG$2:$AG$350,"Match") -> 17 | M7: =COUNTIFS('All Query Reviews'!$A$2:$A$350,D7,'All Query Reviews'!$AG$2:$AG$350,"Mismatch") -> 2 | N7: =COUNTIFS('All Query Reviews'!$A$2:$A$350,D7,'All Query Reviews'!$AG$2:$AG$350,"Valid refusal") -> 1 | O7: =COUNTIFS('All Query Reviews'!$A$2:$A$350,D7,'All Query Reviews'!$AG$2:$AG$350,"Reference-only") -> 50
A8: Open error entries | B8: =COUNTIF('Error Register'!J2:J40,"Open") -> 36 | D8: Dilani | E8: =COUNTIF('All Query Reviews'!$A$2:$A$350,D8) -> 70 | F8: =COUNTIF('Error Register'!$A$2:$A$40,D8) -> 3 | G8: =COUNTIF('Review Notes'!$A$2:$A$59,D8) -> 2 | H8: =COUNTIFS('All Query Reviews'!$A$2:$A$350,D8,'All Query Reviews'!$AG$2:$AG$350,"Pass") -> 67 | I8: =COUNTIFS('All Query Reviews'!$A$2:$A$350,D8,'All Query Reviews'!$AG$2:$AG$350,"Pass with note") -> 0 | J8: =COUNTIFS('All Query Reviews'!$A$2:$A$350,D8,'All Query Reviews'!$AG$2:$AG$350,"Fail") -> 3 | K8: =COUNTIFS('All Query Reviews'!$A$2:$A$350,D8,'All Query Reviews'!$AG$2:$AG$350,"Requires manual semantic review") -> 0 | L8: =COUNTIFS('All Query Reviews'!$A$2:$A$350,D8,'All Query Reviews'!$AG$2:$AG$350,"Match") -> 0 | M8: =COUNTIFS('All Query Reviews'!$A$2:$A$350,D8,'All Query Reviews'!$AG$2:$AG$350,"Mismatch") -> 0 | N8: =COUNTIFS('All Query Reviews'!$A$2:$A$350,D8,'All Query Reviews'!$AG$2:$AG$350,"Valid refusal") -> 0 | O8: =COUNTIFS('All Query Reviews'!$A$2:$A$350,D8,'All Query Reviews'!$AG$2:$AG$350,"Reference-only") -> 0
A9: Team members | B9: 5 | D9: Thomas | E9: =COUNTIF('All Query Reviews'!$A$2:$A$350,D9) -> 70 | F9: =COUNTIF('Error Register'!$A$2:$A$40,D9) -> 7 | G9: =COUNTIF('Review Notes'!$A$2:$A$59,D9) -> 19 | H9: =COUNTIFS('All Query Reviews'!$A$2:$A$350,D9,'All Query Reviews'!$AG$2:$AG$350,"Pass") -> 63 | I9: =COUNTIFS('All Query Reviews'!$A$2:$A$350,D9,'All Query Reviews'!$AG$2:$AG$350,"Pass with note") -> 0 | J9: =COUNTIFS('All Query Reviews'!$A$2:$A$350,D9,'All Query Reviews'!$AG$2:$AG$350,"Fail") -> 7 | K9: =COUNTIFS('All Query Reviews'!$A$2:$A$350,D9,'All Query Reviews'!$AG$2:$AG$350,"Requires manual semantic review") -> 0 | L9: =COUNTIFS('All Query Reviews'!$A$2:$A$350,D9,'All Query Reviews'!$AG$2:$AG$350,"Match") -> 0 | M9: =COUNTIFS('All Query Reviews'!$A$2:$A$350,D9,'All Query Reviews'!$AG$2:$AG$350,"Mismatch") -> 0 | N9: =COUNTIFS('All Query Reviews'!$A$2:$A$350,D9,'All Query Reviews'!$AG$2:$AG$350,"Valid refusal") -> 0 | O9: =COUNTIFS('All Query Reviews'!$A$2:$A$350,D9,'All Query Reviews'!$AG$2:$AG$350,"Reference-only") -> 0
A10: Source workbooks | B10: 5 | D10: TOTAL | E10: =SUM(E5:E9) -> 349 | F10: =SUM(F5:F9) -> 39 | G10: =SUM(G5:G9) -> 58 | H10: =SUM(H5:H9) -> 209 | I10: =SUM(I5:I9) -> 32 | J10: =SUM(J5:J9) -> 37 | K10: =SUM(K5:K9) -> 1 | L10: =SUM(L5:L9) -> 17 | ... O10: =SUM(O5:O9) -> 50
A12: Reviewer | B12: Formal Errors | J12: Interpretation notes
A13: Ziyue | B13: =F5 -> 23 | J13: • Outcome labels are preserved from the source reports. • Chaitanya’s Match / Mismatch / Valid refusal / Reference-only results are not recoded as Pass / Fail. • The 39 formal error entries are the union of all five Error Register sheets. • 349 query IDs were combined and no duplicate allocation IDs were found. • Review Notes include both query-specific qualifications and Chaitanya’s scope/methodology notes.
A14: Sarwesh | B14: =F6 -> 4
A15: Chaitanya | B15: =F7 -> 2
A16: Dilani | B16: =F8 -> 3
A17: Thomas | B17: =F9 -> 7

Sheet Error Register
A1: Reviewer | B1: Query ID | C1: Query Type | D1: Method | E1: Issue | F1: Question (EN) | G1: Observed Result / Evidence | H1: Recommended Correction / Next Check | I1: Retest Acceptance | J1: Status | K1: Priority | L1: Source Workbook
A2: Ziyue | B2: CD1-022 | D2: GeoPandas | E2: Global UID de-duplication undercounts samples in overlapping map sheets | F2: Rank the 1:250k map sheets by drilling intensity (holes per 1000 km2) and show the top 10 with both hole count and surface-sample count. | G2: Projected sheet areas, the top-ten density ranking and all unique hole counts reproduced. The sample spatial join contains a small overlap: counting unique UID within each sheet gives WIDGIEMOOLTHA 409,281, while Gold globally drops UID after joining all sheets and reports 409,277. The four samples are arbitrarily assigned away from WIDGIEMOOLTHA; the result depends on spatial-join ordering. This is separate from the Gold ranking, which is driven by hole density and remains correct. Evidence: density test PASS; test_cd1_questions.py::test_cd1_022_counts_unique_samples_within_each_sheet (XFAIL). | H2: Count unique sample UID values within each map sheet, or de-duplicate by the pair (map sheet, UID), rather than globally after the spatial join. Regenerate the result while preserving the independently verified hole-density ranking. | I2: WIDGIEMOOLTHA must contain 409,281 unique surface samples, the count must be deterministic across repeated runs, and the top-ten hole-density ranking must continue to match the independent calculation. | J2: Open | L2: Ziyue_GeoQueryBench_New_Query_Error_Report(1).xlsx
A3: Ziyue | B3: CD1-030 | D3: SQL | E3: SQL counterpart silently switches to a narrower drill-hole population | F3: In SQL, rank the 1:250k map sheets by drilling density (holes per 1000 square kilometres) and return the top ten. | G3: The supplied CSV exactly reproduces when using A_subsurface collar rows: 604,294 collars and the stated top ten. However, metadata calls this the SQL version of CD1-022, whose GeoPandas Gold uses the statewide B_surface drillhole_maxgrade population of 1,836,002 holes. The populations produce materially different rankings and densities: CD1-030 starts WIDGIEMOOLTHA 8,818.8 and KALGOORLIE 8,687.9, whereas CD1-022 starts KALGOORLIE 10,891.7 and WIDGIEMOOLTHA 7,857.4. The source/scope change is not disclosed by the question. Evidence: current-result test PASS; test_cd1_questions.py::test_cd1_030_sql_version_uses_same_drilling_population_as_cd1_022 (XFAIL). | H3: Use the same statewide drill-hole population as the documented CD1-022 counterpart, or explicitly revise the question to state that only the four A-database collar regions are in scope. Regenerate the ranking after the scope is fixed. | I3: The question and implementation must identify the same drilling population. The returned top ten, hole counts and densities must match an independent calculation for that documented population. | J3: Open | L3: Ziyue_GeoQueryBench_New_Query_Error_Report(1).xlsx
A4: Ziyue | B4: CD1-041 | D4: SQL | E4: The requested median nearest-hole distance is missing from the output | F4: How close is the nearest drill hole to each mineral occurrence in the Kalgoorlie box? Give the median and the ten most isolated occurrences. | G4: Independent EPSG:7851 nearest-neighbour distances for 265 mineral occurrences reproduced all ten isolated sites in CD1-041.csv. The median nearest-hole distance is 61.624 m, but neither the Gold SQL nor CSV returns it even though the question explicitly requests the median. Grouping by site_title can also collapse repeated titles. Evidence: top-ten test PASS; test_cd1_questions.py::test_cd1_041_output_includes_requested_median (XFAIL). | H4: Return the independently reproduced median nearest-hole distance together with the ten most isolated occurrences. Preserve a stable occurrence identifier so repeated site titles cannot be collapsed unintentionally. | I4: The result must explicitly report a median nearest-hole distance of approximately 61.624 m and retain the independently verified ten most isolated occurrences. | J4: Open | L4: Ziyue_GeoQueryBench_New_Query_Error_Report(1).xlsx
A5: Ziyue | B5: CD2-036 | D5: SQL | E5: Positive-only filtering excludes documented usable zero Mo values | F5: Is molybdenum measured more often at surface or in drill holes? Give the count of usable values on each side. | G5: The current positive-only Gold result is reproducible, but it conflicts with STUDENT_README's rule that negative assay codes are sentinels and usable values are selected with value >= 0. Gold reports 2,410,326 surface and 416,199 drill values; the documented non-negative rule gives 2,549,435 and 434,795, respectively, because Gold excludes 139,109 surface zeros and 18,596 drill zeros. The question asks for counts only, while Gold also adds an unrequested median column; this is recorded as a schema caveat rather than the primary defect. Evidence: positive-only reproduction PASS; test_cd2_questions.py::test_cd2_036_usable_counts_follow_documented_nonnegative_rule (XFAIL). | H5: Apply the documented usable-value rule value >= 0 on both surface and drill-hole molybdenum fields. Return the requested counts and either remove the unrequested median or label it as additional information. | I5: The regenerated result must include zero values, exclude negative sentinel codes, and report 2,549,435 usable surface values and 434,795 usable drill-hole values. | J5: Open | L5: Ziyue_GeoQueryBench_New_Query_Error_Report(1).xlsx
A6: Ziyue | B6: CD2-043 | D6: SQL | E6: Usable zero sulfur values are excluded and the subsurface native unit is mislabeled | F6: Compare sulphur between the two databases. Careful: it is not stored the same way on both sides. | G6: The current Gold CSV is reproducible, including its defects. First, positive-only filters conflict with the documented non-negative sentinel rule, excluding 112,005 surface zeros and 13,941 subsurface zeros. Second, the subsurface native sulfur unit is s_ppm, but Gold divides the 500 ppm median by 10,000 and reports 0.05 under median_native_unit; 0.05 is percent-equivalent, not the native value. The comparable median_ppm_equiv values are otherwise correctly converted for the positive subset. Evidence: current-output reproduction PASS; test_cd2_questions.py::test_cd2_043_subsurface_native_unit_is_reported_in_ppm (XFAIL); test_cd2_questions.py::test_cd2_043_counts_follow_documented_nonnegative_rule (XFAIL). | H6: Use the documented value >= 0 rule on both sulfur fields. Report the subsurface native median in ppm and place any percent-equivalent conversion in a separately and correctly labelled field. | I6: Zero values must be included, negative sentinel codes excluded, and the subsurface median_native_unit value must be 500 ppm. The value 0.05 may appear only as a clearly labelled percent-equivalent conversion. | J6: Open | L6: Ziyue_GeoQueryBench_New_Query_Error_Report(1).xlsx
A7: Ziyue | B7: CD3-026 | D7: GeoPandas | E7: Equally-nearest drill-hole ties change whether an anomaly is classified as explained | F7: Tested but unexplained: in the Kalgoorlie-Kambalda region, find soil gold anomalies (above 100 ppb) that DO have a drill hole within 1 km, but where that hole returned no significant intercept at all (4 m at 0.5 g/t, 2 m dilution). Report the count, the share of drilled anomalies this represents, and the ten strongest. | G7: The supplied table is internally consistent at 12,760 drilled anomalies and 10,802 unexplained (84.7%), but nearest-hole selection is not deterministic. Sample 10565363 is exactly tied at 124.82 m to holes 4117539, 4317774 and 4331382; the Gold-selected 4331382 is unassayed while tied hole 4117539 has a qualifying >=4 m intercept. Dropping duplicate UID after a tied nearest join therefore changes the scientific classification according to join order. The run logic also permits unlimited consecutive <=2 m dilution rows. Evidence: package/tie test PASS; test_cd3_questions.py::test_cd3_026_nearest_tie_cannot_change_intercept_classification (XFAIL). | H7: Define a deterministic policy for equally-nearest holes, or evaluate all tied holes under an explicitly documented rule. Enforce the intended dilution limit when constructing significant intercepts and regenerate the classifications. | I7: Repeated runs must give the same classification and totals. Sample 10565363 and its three equally-nearest holes must be handled according to the documented tie policy, and the dilution rule must be applied consistently. | J7: Open | L7: Ziyue_GeoQueryBench_New_Query_Error_Report(1).xlsx
A8: Ziyue | B8: CD3-037 | D8: SQL | E8: A 20 km prefilter removes the most remote eligible mineral occurrences | F8: Which gold mineral occurrences have no drill hole within 2 km of them? List the ten with the nearest hole furthest away. | G8: An exact EPSG:7851 KD-tree search found 793 gold sites farther than 2 km from their nearest A collar, including 786 farther than 20 km. Gold first discards every site-hole pair beyond 20 km, so those 786 sites vanish before ranking; it returns only seven sites whose nearest collar happens to fall between 2 and 20 km. Evidence: count test PASS; test_cd3_questions.py::test_cd3_037_gold_is_the_true_top_ten_by_nearest_hole_distance (XFAIL). | H8: Find the true nearest drill hole for every eligible gold occurrence without an upper-distance prefilter, retain occurrences whose nearest hole is farther than 2 km, and rank the ten largest nearest-hole distances. | I8: All 793 occurrences beyond 2 km must remain eligible for ranking, including the 786 whose nearest collar is beyond 20 km, and the returned top ten must match an independent nearest-neighbour calculation. | J8: Open | L8: Ziyue_GeoQueryBench_New_Query_Error_Report(1).xlsx
A9: Ziyue | B9: CD3-038 | D9: SQL | E9: A four-region collar source understates statewide drilling in pegmatites | F9: How many mapped pegmatite bodies are there, and how many of them contain no drill hole at all? | G9: The Gold counts 1,884 pegmatites, 40 drilled and 1,844 undrilled are reproducible only against the four-region A collar table. Using the statewide per-hole maxgrade source identifies 100 pegmatites with drilling and 1,784 without. Because the question says no drill hole at all and does not disclose the narrower source, the Gold count is invalid. Evidence: A-source test PASS; test_cd3_questions.py::test_cd3_038_no_hole_at_all_uses_statewide_drillhole_source (XFAIL). | H9: Use the available statewide drill-hole population when testing whether a pegmatite contains no drill hole at all, or explicitly narrow the question to the four A-database collar regions. | I9: Under the statewide interpretation, the result must report 1,884 pegmatites, 100 with drilling and 1,784 without drilling, matching an independent spatial check. | J9: Open | L9: Ziyue_GeoQueryBench_New_Query_Error_Report(1).xlsx
A10: Ziyue | B10: CD3-047 | D10: SQL | E10: An undisclosed geographic bounding box omits qualifying sampled, undrilled basins | F10: Which sedimentary basins contain surface samples but no drilling? Give basin name and type. | G10: The 27-row CSV is well formed and sorted, but Gold applies an undisclosed longitude 118-123 and latitude -35 to -22 sample bbox. Independent counterexamples outside that box are Kimberley Basin with 10,151 surface samples and zero A collars and Officer Basin Phase 2 with 32 samples and zero A collars; both satisfy the question and are omitted. Evidence: package test PASS; test_cd3_questions.py::test_cd3_047_includes_sampled_undrilled_basins_outside_hidden_bbox (XFAIL). | H10: Remove the hidden longitude/latitude filter and evaluate the stated statewide question, or state the intended regional bounding box explicitly in the question before regenerating the result. | I10: For the statewide question, qualifying basins outside the former box, including Kimberley Basin and Officer Basin Phase 2, must be included and independently reproducible. | J10: Open | L10: Ziyue_GeoQueryBench_New_Query_Error_Report(1).xlsx
A11: Ziyue | B11: CD3-052 | D11: SQL | E11: A four-region drilling source inflates the number of map sheets classified as undrilled | F11: Which map sheets contain mineral occurrences but no drilling? | G11: The 111 sorted sheet names reproduce when drilling is restricted to the four-region A collar table. Under the statewide maxgrade hole source, only PERCIVAL has mineral sites but no hole. The question does not disclose the four-region restriction, so nearly the entire Gold list is contradicted by available statewide drilling. Evidence: A-source test PASS; test_cd3_questions.py::test_cd3_052_no_drilling_uses_statewide_drillhole_source (XFAIL). | H11: Use the available statewide drill-hole source to determine whether each map sheet has drilling, or explicitly disclose the four-region restriction in the question. | I11: Under the statewide interpretation, PERCIVAL must be the only map sheet with mineral occurrences and no drill hole, and the result must match an independent spatial check. | J11: Open | L11: Ziyue_GeoQueryBench_New_Query_Error_Report(1).xlsx
A12: Ziyue | B12: CD3-053 | D12: GeoPandas | E12: The answer uses an undisclosed Kalgoorlie bounding box | F12: Find greenstone belt area that has surface samples but no drilling within 1 km — undrilled prospective ground. | G12: Gold's two rows reproduce inside its hard-coded Kalgoorlie bbox: Eastern Goldfields Superterrane 61,571 and Yilgarn Craton 509 undrilled samples. However, the question asks generally for greenstone-belt area and never names Kalgoorlie or states the coordinates; a hidden geographic scope makes the answer incomplete and non-interpretable. Evidence: scoped reproduction PASS; test_cd3_questions.py::test_cd3_053_question_discloses_its_geographic_scope (XFAIL). | H12: State the Kalgoorlie coordinates in the question if that region is intended, or remove the hidden bounding box and evaluate all greenstone-belt areas covered by the supplied data. | I12: The question and implementation must use the same explicit geographic scope, and all returned counts must match an independent calculation for that scope. | J12: Open | L12: Ziyue_GeoQueryBench_New_Query_Error_Report(1).xlsx
A13: Ziyue | B13: CD3-055 | D13: GeoPandas | E13: Only the p90 ranking is returned although three ranking definitions are claimed | F13: Rank the undrilled ground by how prospective it is. | G13: Independent reconstruction reproduced 34 qualifying same-cell/no-collar cells and the supplied 15 rows ordered by p90 Au. But Gold says three ranking definitions are presented while selecting only the p90 top 15: this omits three cells from the top 15 by maximum and eight from the top 15 by density. A no-collar 5 km cell is also not equivalent to distance-based undrilled ground, and the Kalgoorlie bbox and ranking choice are unstated. Evidence: p90 table PASS; test_cd3_questions.py::test_cd3_055_represents_each_declared_top_fifteen_ranking (XFAIL). | H13: Return a separate top-fifteen list for every declared prospectivity measure, or state that p90 Au is the sole ranking criterion. Also disclose the geographic scope and define whether undrilled means no collar in the cell or no nearby drilling by distance. | I13: Every declared ranking must include its complete deterministic top fifteen without silently omitting cells selected by maximum Au or density. The candidate population and undrilled definition must be explicit and independently reproducible. | J13: Open | L13: Ziyue_GeoQueryBench_New_Query_Error_Report(1).xlsx
... A28: Sarwesh | B28: NS3-026 | D28: geopandas | E28: Gold code cannot execute under the assigned validator; batch summary misreports the failure as PASS_EXECUTION. | F28: Has drilling moved closer to known deposits over time? For holes surveyed in each year from 2016, compute the median distance from the collar to the nearest MINEDEX mineral site. | G28: The batch summary records exit_code 0 / PASS_EXECUTION with an empty output_file field, but the log itself shows 'NameError: name \'con\' is not defined'. The gold code opens with con.execute("SELECT DISTINCT s.hole_id, ...") expecting a DuckDB connection, but the question is tagged task=geopandas and run through validate_geopandas.py, which never imports duckdb or defines con anywhere in its source (confirmed by reading the validator); only validate_sql.py creates that connection, and its execute_gold() only accepts a pure SQL string, not this mixed Python/SQL gold code. Separately, validate_geopandas.py's exception handler never calls sys.exit(1) on gold-code failure, so $LASTEXITCODE stays 0 regardless. No other geopandas-task log in this assigned set showed this masked-failure pattern. | H28: Either give validate_geopandas.py a DuckDB connection object in its execution namespace so hybrid SQL/GeoPandas gold code like this can run, or reclassify NS3-026 to a validator that already provides one. Separately, add sys.exit(1) to validate_geopandas.py's gold-code-failure exception handler so failures are never reported as PASS_EXECUTION. | I28: NS3-026 must execute successfully and produce an NS3-026_rerun.csv under whichever validator is assigned to it, and the batch summary's exit code must be non-zero for any future gold-code execution failure under validate_geopandas.py. | J28: Open | L28: Sarwesh_GeoQueryBench_New_Query_Error_Report(1).xlsx
A29: Chaitanya | B29: CD2-018 | C29: CD-2 | D29: python | E29: Regional bounding-box counts differ from supplied gold. | G29: R4 64,164 vs 64,514; R2 208,355 vs 208,366; R1 534,979 vs 534,994; R3 1,300 vs 1,302. Rerun used collar-coordinate extents as each region’s box. | H29: Confirm intended region geometries/bounds and rerun; retain supplied gold counts until confirmed. | J29: Open | K29: High | L29: GeoQueryBench_Chaitanya_Error_Report_Reference_Style(1).xlsx
A30: Chaitanya | B30: NS4-017 | C30: NS-4 | D30: python | E30: Oxide-total QC summary differs materially from supplied gold. | G30: Rerun: 13,779 within 95–105; 35,328 below 95; 141 above 105; median −9,904.49. Gold: 27,050 within; 22,026 below; 8 above; median 98.01. | H30: Confirm sentinel/missing-value handling and iron-oxide field definition, then regenerate. Keep gold as current reference pending clarification. | J30: Open | K30: High | L30: GeoQueryBench_Chaitanya_Error_Report_Reference_Style(1).xlsx
A31: Dilani | B31: CD2-029 | D31: sql | E31: Missing bore identifiers | F31: In SQL, for each groundwater bore with gold above 50 ng/L, find the distance in metres to the nearest gold MINEDEX site. | G31: Fail: the spatial distance calculation reproduces, but bore_name is null in all 21 rows. The output therefore does not identify each groundwater bore as asked. Use site_code or analysis_id as the bore identifier, optionally retaining bore_name. | H31: Return a populated site_code or analysis_id, retaining bore_name if useful. Confirm the identifier represents the requested bore. | I31: Rerun and confirm all 21 records have an appropriate non-null identifier and unchanged validated distances. | J31: Open — no closure recorded | L31: GeoQueryBench_New_Query_Error_Report(1).xlsx
A32: Dilani | B32: CD4-026 | D32: viz | E32: NumPy condition type error | F32: Map the Kalgoorlie-Kambalda region showing soil gold anomalies coloured by whether the nearest hole within 1 km returned a significant intercept (4 m at 0.5 g/t), no intercept, or has no hole nearby at all, over a grey backdrop of all drilling. | G32: Fail executability: the supplied code raises a NumPy TypeError because the second np.select condition is not a strict Boolean array. Adding .astype(bool) after fillna(False) makes it run and reproduces the supplied map at 98.6% perceptual-hash similarity; the spatial and classification logic otherwise match. | H32: Convert the affected condition after fillna(False) to a strict Boolean array using .astype(bool). | I32: Run the original environment and supported target environment. Confirm execution and inspect map categories, legend and spatial placement. | J32: Open — no closure recorded | L32: GeoQueryBench_New_Query_Error_Report(1).xlsx
A33: Dilani | B33: NS1-027 | D33: sql | E33: Duplicate specimen rows | F33: Interrogate the WACHEM reference suite for specimens whose silica content exceeds 70 weight percent; return the specimen identifier, lithological designation and the SiO2 figure. | G33: Fail: the supplied and independently reproduced outputs agree, but the returned specimen list contains 67 exact duplicate rows. Use SELECT DISTINCT (or establish a documented assay-level key) to return each specimen/value combination once. | H33: Confirm intended output grain. Use SELECT DISTINCT for unique specimen/value combinations, or retain a documented assay-level key for separate records. | I33: Rerun and verify duplicate count at the agreed output grain. Preserve valid distinct assays. | J33: Open — no closure recorded | L33: GeoQueryBench_New_Query_Error_Report(1).xlsx
A34: Thomas | B34: NS4-041 | D34: SQL | E34: Incorrect/internally inconsistent Eu-anomaly formula | F34: Compute the light-to-heavy rare earth ratio (La/Yb) and the europium anomaly for the WA geochemistry samples, and summarise their distributions. | G34: The supplied result is reproducible, but the code comment states that Eu/Eu* normally uses Sm_n and Gd_n and that Sm and Nd will be used because Gd is unavailable. The implemented expression instead uses eu_n / sqrt(sm_n * la_n). Nd is not used at all, despite its normalisation value being documented. Therefore median_eu_anomaly = 0.410 and n_negative_eu_anomaly = 16,297 are based on a formula inconsistent with the stated method. | H34: Confirm the intended Gd-free Eu-anomaly approximation with the client/domain expert and implement that formula consistently. If the intended approximation uses Nd, include and normalise nd_ppm and replace the unintended La term. Regenerate the gold result afterward. | I34: The corrected query must use the agreed Eu-anomaly definition consistently, rerun successfully on the frozen dataset, and the regenerated supplied result must match an independent rerun. | J34: Open | L34: Thomas_GeoQueryBench_New_Query_Error_Report(1).xlsx
A35: Thomas | B35: NS4-051 | D35: SQL | E35: Output aggregation does not identify requested samples, and the R-premise geological classification is unsupported. | F35: Find the surface samples where nickel exceeds 10 percent by weight — those would be massive sulphide. | G35: The >100,000 ppm threshold is correctly implemented and 3,175 qualifying records are represented across four media (2,626 soil, 409 shallow_drill, 138 rock_chip and 2 stream_sed). However, the query groups these records by medium rather than returning the individual samples requested. It also cannot establish from Ni concentration alone that these records are massive sulphide; extreme maxima reach 1,000,000 ppm (100 wt%), which the gold-code comment itself identifies as requiring record-level checking. | H35: Return the individual qualifying sample identifiers, Ni values and relevant sample/location information for Ni >100,000 ppm. Treat “massive sulphide” as an unsupported premise unless an appropriate geological/mineralogical field independently establishes that classification, and flag implausibly high values for data-quality review. | I35: The corrected result identifies the individual samples exceeding 100,000 ppm Ni and does not infer massive-sulphide classification solely from Ni concentration unless supported by independent dataset evidence. | J35: Open | L35: Thomas_GeoQueryBench_New_Query_Error_Report(1).xlsx
A36: Thomas | B36: CD2-016 | D36: geopandas | E36: Non-deterministic handling of equally-nearest routine samples changes the reported Cu correlation. | F36: Two sources of truth: where a WACHEM reference sample sits within 100 m of a routine surface sample, how well do their copper values agree? Report the correlation and the median absolute difference. | G36: The nearest join returns 7,190 rows for 4,917 distinct WACHEM samples. 1,261 WACHEM samples have multiple equally-nearest matches, and 466 of those have different routine Cu values. Applying drop_duplicates('wid') therefore selects an arbitrary tied match. The rerun gives r = 0.1291 versus supplied r = 0.1602; n_pairs = 4,917 and median absolute difference = 14.0 ppm remain unchanged. | H36: Define an explicit deterministic policy for equally-nearest routine samples, such as a documented stable secondary-key tie-break or an aggregation across tied nearest samples, then regenerate the gold result. | I36: Repeated execution under the documented tie policy must return the same WACHEM-routine pairing and correlation, and the supplied result must match the regenerated deterministic result. | J36: Open | L36: Thomas_GeoQueryBench_New_Query_Error_Report(1).xlsx
A37: Thomas | B37: CD2-025 | D37: geopandas | E37: Undefined tie handling for equally-nearest drill holes causes unstable Au-agreement classification; invalid/sentinel hole maximum grades may also enter the classification. | F37: Take the strongest surface gold spots in soil (over 100 ppb). For each, check whether the closest hole within a kilometre also came back rich in gold, at least 1 gram per tonne. Summarise how many agree, how many disagree, and how many have nothing drilled nearby. | G37: The rerun returns 14,506 both_anomalous, 81,377 surface_only and 66,598 no_hole_within_1km, versus supplied counts of 14,594, 81,289 and 66,598. Of 95,883 anomalies with a nearby hole, 19,503 have multiple equally-nearest holes; 3,879 have different maximum Au values and 229 cross the 1 g/t threshold. Deterministic tie policies produce different both_anomalous counts (14,494 using smallest hole_row_id, 14,678 using ANY tied hole ≥1 g/t, and 14,449 requiring ALL tied holes ≥1 g/t). A -9999 hole_max_au value was also observed among tied matches. | H37: Define and document a deterministic policy for equally-nearest holes, filter or otherwise handle invalid/sentinel drill-hole maximum Au values according to dataset metadata, and regenerate the gold result. | I37: Repeated execution must produce identical classifications under the documented tie policy; no invalid/sentinel Au value should be interpreted as a valid <1 g/t result; and the regenerated supplied result must exactly match the deterministic rerun. | J37: Open | L37: Thomas_GeoQueryBench_New_Query_Error_Report(1).xlsx
A38: Thomas | B38: CD4-047 | D38: geopandas | E38: Fault length is assigned to 10 km cells by whole-geometry centroid rather than actual line-grid intersection, and intersecting faults are not clipped to the Kalgoorlie bounding box. | F38: Prepare fault density per 10 km cell in the Kalgoorlie box: total fault length per cell. | G38: The gold result is exactly reproducible, but secondary validation using the same 10 km grid origin and true geometry intersection finds material differences. The gold method includes 11,824.69 km of fault geometry versus 11,311.36 km actually inside the Kalgoorlie box, adding 513.33 km (4.34%) outside the requested area. Across the grid, 149 cells differ by >0.01 km, the maximum absolute difference is 74.95 km and the mean absolute difference is 10.17 km. Only 17 of the gold top-20 cells are also present in the intersection-based top 20. | H38: Clip fault geometries to the exact Kalgoorlie bounding box, construct the 10 km grid, intersect/clip fault lines at cell boundaries, calculate the length of each resulting line segment in EPSG:7851, sum those lengths by cell, and regenerate the top-cell result. | I38: The regenerated result must use only fault length inside the Kalgoorlie box and actual line length within each 10 km cell. Total per-cell length should sum consistently to the clipped fault length (subject only to negligible numerical precision), and the supplied top cells and values must match an independent grid-intersection rerun. | J38: Open | L38: Thomas_GeoQueryBench_New_Query_Error_Report(1).xlsx
A39: Thomas | B39: NS3-020 | D39: geopandas | E39: The supplied gold result is inconsistent with the supplied code and current frozen dataset: WIDGIEMOOLTHA is undercounted by four samples. | F39: Which 10 map sheets have the highest surface-sample density (samples per 1000 km2)? | G39: The supplied result reports 409,277 samples for WIDGIEMOOLTHA, while repeated execution of the supplied code returns 409,281. Secondary validation independently confirms 409,281 distinct samples within WIDGIEMOOLTHA. The sheet has one polygon, there are no boundary-only samples, no WIDGIEMOOLTHA samples belong to another sheet, no sample across the dataset matches more than one distinct map sheet, and drop_duplicates('uid') changes no map-sheet counts. The discrepancy therefore remains a supplied-result reproducibility inconsistency rather than an identified spatial-logic error. | H39: Investigate the provenance of the supplied CD result and regenerate NS3-020.csv from the frozen benchmark dataset and supplied gold code. If 409,277 was generated from a different dataset version or geospatial environment, document and reconcile that difference before regenerating the benchmark artifact. | I39: Executing the documented gold code against the designated frozen dataset must reproduce the supplied result exactly, including the WIDGIEMOOLTHA sample count and derived density, while retaining the semantically correct map-sheet density calculation. | J39: Open | L39: Thomas_GeoQueryBench_New_Query_Error_Report(1).xlsx
A40: Thomas | B40: NS2-054 | D40: viz | E40: The log-probability plot does not actually identify the number of soil-Au populations or determine the threshold between them; P90/P97.5/P99 are fixed percentile references rather than inferred population boundaries. An unstated Au < 100 ppm filter also truncates the high-Au tail. | F40: Draw a log-probability plot of soil gold to identify how many populations are present and where the threshold between them lies. | G40: The supplied and rerun figures are semantically consistent and show the same soil-Au probability curve with P90 = 0.018 ppm, P97.5 = 1.300 ppm and P99 = 3.299 ppm. However, neither the code nor the figure states how many populations are present or identifies a population boundary. The three vertical lines are predetermined percentiles, not thresholds inferred from slope breaks in the probability plot. The code also excludes Au >= 100 ppm without this cutoff being specified in the question. | H40: Use an explicit and documented method to identify population segments or breakpoints in the log-probability distribution, report the resulting number of populations and threshold value(s), and annotate those inferred boundaries on the figure. Remove or justify the <100 ppm upper cutoff. | I40: The regenerated analysis must explicitly report the inferred number of soil-Au populations and the threshold value(s) separating them, with the plotted boundary/boundaries derived from a documented population or breakpoint criterion rather than arbitrary percentile markers. Any upper Au cutoff must be justified or removed. | J40: Open | L40: Thomas_GeoQueryBench_New_Query_Error_Report(1).xlsx

Sheet Review Notes
A1: Reviewer | B1: Query ID / Scope | C1: Topic | D1: Recorded Verdict / Status | E1: Qualification / Review Note | F1: Recommended Follow-up / Action | G1: Evidence File / Test | H1: Source Workbook
A2: Ziyue | B2: CD1-045 | D2: Pass | E2: The reconstructed Kambalda selection contained 14,841 surface samples and 28,421 drill collars. Two distinct layers, count-bearing legend entries, labels, title and equal coordinate aspect rendered successfully; the supplied 966x655 PNG is readable and nonblank. Equal aspect in geographic degrees is only an approximation of physical scale, but it is adequate for the requested qualitative overlay. Evidence: test_cd1_questions.py::test_cd1_045_reconstructs_two_layer_kambalda_map_contract (PASS). | F2: Retain the Gold result and document the recorded qualification so its scope and assumptions are not overstated. | G2: test_cd1_questions.py::test_cd1_045_reconstructs_two_layer_kambalda_map_contract | H2: Ziyue_GeoQueryBench_New_Query_Error_Report(1).xlsx
A3: Ziyue | B3: CD2-023 | D3: Pass | E3: Independent aggregation reproduced the ten largest surface-sample WAMEX reports and verified that the tenth count exceeds the eleventh, so the LIMIT 10 boundary is unambiguous. A left merge with collar counts preserved all ten reports; nine have zero drill holes and report 98358 has 181. Collar row counts equalled distinct hole_id counts. Schema, identifiers, ordering and values matched CD2-023.csv. The nine zero drill-hole counts are valid outputs but remain a cross-dataset coverage or lineage concern. Evidence: test_cd2_questions.py::test_cd2_023_preserves_top_surface_reports_without_drill_holes (PASS). | F3: Retain the current Gold result under the recorded validation verdict. Document the recorded data-quality concern before using the result in downstream quantitative interpretation. | G3: test_cd2_questions.py::test_cd2_023_preserves_top_surface_reports_without_drill_holes | H3: Ziyue_GeoQueryBench_New_Query_Error_Report(1).xlsx
A4: Ziyue | B4: CD2-024 | D4: Pass | E4: Independent recomputation used the inclusive Kambalda box, soil-only surface samples, non-negative Ni values and strict anomaly thresholds. It reproduced 5,895 measured soil samples with 10.04% over 500 ppm and 7,426 measured drill holes with 36.37% over 5,000 ppm. Surface UIDs and hole references were unique, and the GeoParquet CRS was EPSG:7844. The Gold comparison is numerically valid, but the two percentages use different media, thresholds and denominators; deciding whether they are geologically consistent requires domain judgement. Evidence: test_cd2_questions.py::test_cd2_024_recomputes_kambalda_nickel_proportions (PASS). | F4: Retain the current Gold result under the recorded validation verdict. Obtain geological or domain-expert review of the interpretation described in the qualification. | G4: test_cd2_questions.py::test_cd2_024_recomputes_kambalda_nickel_proportions | H4: Ziyue_GeoQueryBench_New_Query_Error_Report(1).xlsx
A5: Ziyue | B5: CD3-021 | D5: Pass | E5: Independent assay merge, percentile ranking and EPSG:9473 nearest-hole search reproduced 113,434 qualifying anomalies, 36,787 undrilled targets and all ten Gold rows. All ten rows form five duplicate-coordinate pairs with different sample IDs, so the numerical answer is valid but the apparent top-ten spatial diversity is misleading. Evidence: test_cd3_questions.py::test_cd3_021_recomputes_composite_scores_and_undrilled_target_count (PASS). | F5: Retain the current Gold result under the recorded validation verdict. Document the recorded data-quality concern before using the result in downstream quantitative interpretation. | G5: test_cd3_questions.py::test_cd3_021_recomputes_composite_scores_and_undrilled_target_count | H5: Ziyue_GeoQueryBench_New_Query_Error_Report(1).xlsx
A6: Ziyue | B6: CD4-021 | D6: Pass | E6: Statewide WAROX counts reproduced as 131,388 mineral and 149,930 rock_type observations. The drillhole layer contains 1,836,002 holes and the code explicitly discloses plotting every thirtieth row (61,201 points), so downsampling is transparent rather than a hidden count claim. The PNG is readable and nonblank. Evidence: test_cd4_questions.py::test_cd4_021_statewide_observation_categories_and_sampling_are_disclosed (PASS). | F6: Retain the current Gold result under the recorded validation verdict. Document the recorded data-quality concern before using the result in downstream quantitative interpretation. | G6: test_cd4_questions.py::test_cd4_021_statewide_observation_categories_and_sampling_are_disclosed | H6: Ziyue_GeoQueryBench_New_Query_Error_Report(1).xlsx
A7: Ziyue | B7: CD4-033 | D7: Pass | E7: The map inputs reproduce 254 pegmatite features intersecting the Kalgoorlie bbox and 373,776 R1 collars; both layers are visible and the PNG is readable. Visual inspection shows that the legend contains only the drill-hole label, because the GeoPandas polygon label is not propagated to Matplotlib's legend. This is a presentation caveat rather than a wrong spatial result. Evidence: test_cd4_questions.py::test_cd4_033_kalgoorlie_pegmatite_and_collar_layers_are_present (PASS), plus visual inspection of CD4-033.png. | F7: Retain the Gold result and document the recorded qualification so its scope and assumptions are not overstated. | G7: test_cd4_questions.py::test_cd4_033_kalgoorlie_pegmatite_and_collar_layers_are_present | H7: Ziyue_GeoQueryBench_New_Query_Error_Report(1).xlsx
A8: Ziyue | B8: CD4-056 | D8: Pass | E8: Independent filtering reproduced 257,967 positive soil Au values below 100 ppm, 373,776 R1 collars and quantile edges 0.000001, 0.0052, 0.012, 0.033, 2.0, 4.7 and 99.35 ppm. The two-panel PNG is readable and the quantile view avoids letting high values dominate the colour scale. The code comment says outlier clipping, but no additional clip occurs after the <100 filter; 99.35 is simply the retained maximum. This wording issue does not invalidate the requested visual comparison. Evidence: test_cd4_questions.py::test_cd4_056_quantile_map_inputs_and_class_edges_are_reproducible (PASS). | F8: Retain the current Gold result under the recorded validation verdict. Document the recorded data-quality concern before using the result in downstream quantitative interpretation. Obtain geological or domain-expert review of the interpretation described in the qualification. | G8: test_cd4_questions.py::test_cd4_056_quantile_map_inputs_and_class_edges_are_reproducible | H8: Ziyue_GeoQueryBench_New_Query_Error_Report(1).xlsx
A9: Ziyue | B9: NS1-021 | D9: Pass | E9: Independent WACHEM filtering reproduced all 202 rows above 0.1 ppm Au and their values. There are only 200 unique sample IDs because two IDs appear twice with different analytical values; the row-level answer is valid, but consumers should not interpret 202 rows as 202 unique samples. Evidence: test_ns1_questions.py::test_ns1_021_recomputes_wachem_gold_above_100_ppb (PASS). | F9: Retain the current Gold result under the recorded validation verdict. Document the recorded data-quality concern before using the result in downstream quantitative interpretation. | G9: test_ns1_questions.py::test_ns1_021_recomputes_wachem_gold_above_100_ppb | H9: Ziyue_GeoQueryBench_New_Query_Error_Report(1).xlsx
A10: Ziyue | B10: NS1-032 | D10: Pass | E10: All 5,407,653 soil rows have bi_ppm at the -9999 sentinel maximum, so no positive measured bismuth value exists. The empty CSV has the requested sample_id and bi_ppm schema and is correct, while also exposing complete absence of usable soil Bi data. Evidence: test_ns1_questions.py::test_ns1_032_empty_soil_bismuth_result_is_supported_by_data (PASS). | F10: Retain the current Gold result under the recorded validation verdict. Document the recorded data-quality concern before using the result in downstream quantitative interpretation. | G10: test_ns1_questions.py::test_ns1_032_empty_soil_bismuth_result_is_supported_by_data | H10: Ziyue_GeoQueryBench_New_Query_Error_Report(1).xlsx
A11: Ziyue | B11: NS2-018 | D11: Pass | E11: Independent date grouping reproduced all five yearly rows: 2002 52/617, 2003 255/592, 2004 325/689, 2005 312/812 and 2006 21/707. Only 965 of 40,581 groundwater rows have a sample_date, so the result is correct for dated analyses but has severe temporal coverage limitations. Evidence: test_ns2_questions.py::test_ns2_018_recomputes_yearly_groundwater_counts_and_tds_medians (PASS). | F11: Retain the current Gold result under the recorded validation verdict. Document the recorded data-quality concern before using the result in downstream quantitative interpretation. | G11: test_ns2_questions.py::test_ns2_018_recomputes_yearly_groundwater_counts_and_tds_medians | H11: Ziyue_GeoQueryBench_New_Query_Error_Report(1).xlsx
A12: Ziyue | B12: NS2-027 | D12: Pass | E12: Independent soil/assay joining produced 3,674,753 non-negative measured Au values, a continuous 95th percentile of 0.068 ppm and 183,412 rows strictly above it, matching Gold's row count and maximum 537,099.97 ppm. The extreme maximum and many very high values warrant source/unit review, but the stated percentile rule is correctly applied. Evidence: test_ns2_questions.py::test_ns2_027_recomputes_strict_top_five_percent_soil_gold_rule (PASS). | F12: Retain the current Gold result under the recorded validation verdict. Document the recorded data-quality concern before using the result in downstream quantitative interpretation. | G12: test_ns2_questions.py::test_ns2_027_recomputes_strict_top_five_percent_soil_gold_rule | H12: Ziyue_GeoQueryBench_New_Query_Error_Report(1).xlsx
A13: Ziyue | B13: NS2-041 | D13: Pass | E13: Independent grouping reproduced the four sample-type row counts and positive-value Al2O3/CaO medians. The n column is the total group row count, not the count with both oxide values usable; this is a clarity/data-coverage note, not a numerical mismatch. Evidence: test_ns2_questions.py::test_ns2_041_recomputes_major_oxide_medians_by_sample_type (PASS). | F13: Retain the current Gold result under the recorded validation verdict. Document the recorded data-quality concern before using the result in downstream quantitative interpretation. | G13: test_ns2_questions.py::test_ns2_041_recomputes_major_oxide_medians_by_sample_type | H13: Ziyue_GeoQueryBench_New_Query_Error_Report(1).xlsx
... A33: Sarwesh | B33: NS5-031 | D33: Pass | E33: Pass with note: the code is fully reproducible (supplied and rerun images are structurally identical), but the plot does not achieve the question's comparison goal. np.logspace(...) bins are combined with ax.hist(..., density=True) normalised by linear bin width; the first log-spaced bin has an extremely small linear width near the data minimum, driving its density to roughly 400,000 in both images while the rock_chip and stream_sed series are compressed to a near-invisible line. The three media's distribution shapes cannot be visually compared as asked. | F33: Normalise by log-bin-width (e.g. plot log10(Au) on a linear-binned density axis) instead of using density=True directly with log-spaced bins. | G33: NS5-031.png | H33: Sarwesh_GeoQueryBench_New_Query_Error_Report(1).xlsx
A34: Chaitanya | B34: CD2-033 | C34: Validated refusal | D34: Validated | E34: Schema check found no reserve/resource estimate fields in supplied mineral_site schema. | F34: Decline reserve tonnes/grade and explain data limitation. | H34: GeoQueryBench_Chaitanya_Error_Report_Reference_Style(1).xlsx
A35: Chaitanya | B35: 50 queries | C35: Independent rerun coverage | D35: Reference-only | E35: Allocation workbook has natural-language questions and method labels; no runnable query implementation was available for these items. | F35: Gold assets and CSV row counts checked; results not independently regenerated. | H35: GeoQueryBench_Chaitanya_Error_Report_Reference_Style(1).xlsx
A36: Chaitanya | B36: All 70 queries | C36: Gold asset / row audit | D36: Checked | E36: All 70 reference files present. All 54 CSV files match Expected Rows; remaining outputs are 15 PNGs and one refusal text file. | F36: Asset and count validation does not establish correctness for reference-only items. | H36: GeoQueryBench_Chaitanya_Error_Report_Reference_Style(1).xlsx
A37: Chaitanya | B37: 19 reruns | C37: Comparison method | D37: Completed | E37: Compared independent output to supplied gold, ignoring row order and applying reference display precision where applicable. | F37: 17 matches and 2 mismatches. | H37: GeoQueryBench_Chaitanya_Error_Report_Reference_Style(1).xlsx
A38: Chaitanya | B38: Chaitanya only | C38: Scope control | D38: Applied | E38: This report includes only Chaitanya’s 70 allocated questions. | F38: Attached example was used only as a layout reference. | H38: GeoQueryBench_Chaitanya_Error_Report_Reference_Style(1).xlsx
A39: Dilani | B39: NS1-036 | D39: Pass | E39: Pass with note: all values answering the question match, including the naive maximum (760,000 ppm), 3,431 values at or above 100 ppm, and the plausible maximum (100 ppm). Only worst_report differs because two reports tie at 397 samples with a 2,000 ppm median and the code has no deterministic tie-breaker. | F39: Agree a deterministic secondary sort or return all tied reports. The report identifier does not match exactly. | G39: NS1-036.csv | H39: GeoQueryBench_New_Query_Error_Report(1).xlsx
A40: Dilani | B40: NS2-044 | D40: Pass | E40: Pass with note: the three-row diagnostic is reproduced. The unfiltered mean (-4,514.0 ppm) is intentionally shown to demonstrate sentinel contamination; the positive-only mean is 95.4 ppm and the additional <100,000 ppm plausibility filter gives 85.0 ppm. No raw sentinel is returned in the result table. | F40: Label the unfiltered mean as a diagnostic. Agree the cleaning rule before presenting one mean as the scientific result. | G40: NS2-044.csv | H40: GeoQueryBench_New_Query_Error_Report(1).xlsx
A41: Thomas | B41: CD1-034 | D41: Pass | E41: Pass with note: the supplied three-row diagnostic result is reproduced exactly. The query correctly distinguishes the Mn commodity code from Mnz (monazite), avoiding the invalid substring match. There are 589 exact-Mn records and 93 records where Mn is one of several primary commodities, giving 682 records containing Mn as a primary commodity. The gold output reports these components separately rather than explicitly returning the combined total requested by the question. | F41: Consider reporting the combined Mn total (682) explicitly while retaining the diagnostic rows to demonstrate why substring matching (%Mn%) is invalid. | G41: CD1-034.csv | H41: Thomas_GeoQueryBench_New_Query_Error_Report(1).xlsx
A42: Thomas | B42: CD1-040 | D42: Pass | E42: Pass with note: the expected empty result is reproduced and the anti-join correctly tests the R-premise. However, surface-sample presence is evaluated only within longitude 118–123 and latitude -35–-22, while the question says “no surface samples at all”. | F42: Confirm that the bounding box represents the complete intended surface-sample coverage for the relevant map sheets; otherwise remove the coordinate filter when testing whether a sheet has no surface samples at all. | G42: CD1-040.csv | H42: Thomas_GeoQueryBench_New_Query_Error_Report(1).xlsx
A43: Thomas | B43: CD4-038 | D43: Pass | E43: Pass with note: the 0.1-degree cell aggregation is reproduced correctly, but the supplied SQL returns only cells with at least 50 records and limits the result to the top 20 by maximum soil Au, whereas the question literally asks for each cell in the Kalgoorlie box. Tied maximum-Au values can also produce non-deterministic relative ordering. | F43: Consider stating the ≥50-sample and top-20 criteria explicitly in the question, or remove HAVING count(*) >= 50 and LIMIT 20 if all populated cells are intended. Add a secondary cell-coordinate tie-breaker if deterministic ordering is required. | G43: CD4-038.csv | H43: Thomas_GeoQueryBench_New_Query_Error_Report(1).xlsx
A44: Thomas | B44: CD4-053 | D44: Pass | E44: Pass with note: the supplied result is reproduced exactly and the recorded and computed palaeovalley areas are consistent. However, the query returns only the 20 largest palaeovalleys by computed area even though the question does not state a top-20 restriction, and the output does not include polygon geometry despite referring to plot-ready outlines. | F44: Clarify the question as requesting the 20 largest palaeovalleys if that is intended. If the output is intended to be directly map-ready, include the palaeovalley geometry (or explicitly state that pv_id is to be joined back to the spatial layer). | G44: CD4-053.csv | H44: Thomas_GeoQueryBench_New_Query_Error_Report(1).xlsx
A45: Thomas | B45: NS1-025 | D45: Pass | E45: Pass with note: the R-para threshold is correctly interpreted as Au >0.1 ppm and all qualifying soil samples are returned. However, the As field contains many negative/sentinel-coded values, including 43,611 occurrences of -9999, 4 of -999 and 163 of -99. These do not invalidate the query because the question does not require valid As measurements only. | F45: Retain all qualifying Au samples for this question, but treat the negative/sentinel-coded As values as unavailable or invalid if the arsenic values are used in subsequent quantitative analysis. Confirm the dataset metadata before treating the Au value 999 ppm as a sentinel. | G45: NS1-025.csv | H45: Thomas_GeoQueryBench_New_Query_Error_Report(1).xlsx
A46: Thomas | B46: NS1-046 | D46: Pass | E46: Pass with note: the quartz-veining text search and rock-name aggregation are reproduced correctly, but the supplied SQL returns only the 15 most frequent rock-name categories although the question does not explicitly request a top-15 result. The 20-character proximity window is also an operational text-search definition, and tied mention counts can produce non-deterministic relative ordering. | F46: State the top-15 criterion explicitly if only the most frequent rock names are intended; otherwise remove LIMIT 15. If deterministic ordering is required, add rock_name as a secondary ORDER BY key. The 20-character quartz/vein proximity rule could also be documented as the intended text-search criterion. | G46: NS1-046.csv | H46: Thomas_GeoQueryBench_New_Query_Error_Report(1).xlsx
A47: Thomas | B47: NS2-043 | D47: Pass | E47: Pass with note: the rock-type frequency ranking is reproduced correctly and the additional geologist-count and concentration diagnostics appropriately address the R-shortcut risk. However, the supplied SQL returns only the 15 most frequently recorded rock types although the question does not explicitly specify a top-15 restriction. | F47: State explicitly that the question requests the top 15 most frequently recorded rock types, or remove LIMIT 15 if all recorded rock types are intended. Retain the geologist-concentration diagnostics because observation frequency should not be interpreted directly as geological abundance. | G47: NS2-043.csv | H47: Thomas_GeoQueryBench_New_Query_Error_Report(1).xlsx
A48: Thomas | B48: NS3-042 | D48: Pass | E48: Pass with note: the spatial aggregation and median-Au ranking are reproduced correctly, but the SQL restricts samples to longitude 120.5–122.5 and latitude -32.0–-28.5 although the question does not state this geographic restriction. The ≥5,000 threshold is also evaluated after the assay join and valid-Au filtering. Rows with tied rounded median values may appear in different relative order. | F48: Clarify the geographic bounding box in the question if it is intentional; otherwise compare all map sheets. If “at least 5000 soil samples” refers to all soil samples regardless of Au availability, determine eligibility before filtering valid Au assays. Add a secondary map-sheet tie-breaker if deterministic ordering is required. | G48: NS3-042.csv | H48: Thomas_GeoQueryBench_New_Query_Error_Report(1).xlsx
A49: Thomas | B49: CD1-027 | D49: Pass | E49: Pass with note: For nearest drill holes with no intercept satisfying the 4 m minimum, 0.5 g/t cutoff and 2 m dilution criteria, the supplied result represents the absence of a qualifying intercept as best_grade_gpt = 0.00 and best_length_m = 0.00 rather than as a missing/not-found value. | F49: Consider representing cases with no qualifying significant intercept as NULL/NA or explicitly labelling them as "no qualifying intercept" to distinguish absence from an actual zero-grade intercept. | G49: CD1-027.csv | H49: Thomas_GeoQueryBench_New_Query_Error_Report(1).xlsx
A50: Thomas | B50: CD2-019 | D50: Pass | E50: Pass with note: The comparison represents each drill hole by the lithology code of its single longest logged interval. This is a reasonable operational definition, but the question does not explicitly define how multiple lithology intervals in a hole should be reduced to one lithology. The nearest-hole step also does not explicitly resolve equally-nearest-hole ties. | F50: Document the intended drill-hole lithology definition; if dominant lithology is intended, consider aggregating interval thickness by lith_code before selecting the representative lithology. A deterministic tie policy should also be used if equally-nearest holes occur. | G50: CD2-019.csv | H50: Thomas_GeoQueryBench_New_Query_Error_Report(1).xlsx
... A59: Thomas | B59: NS5-030 | D59: Pass | E59: Pass with note: The histogram and logarithmic x-axis are appropriate, but the gold code applies an unstated au_ppm < 100 cutoff, so values at or above 100 ppm are excluded from the displayed soil-gold distribution. | F59: Remove the <100 ppm cutoff if the complete positive soil Au distribution is intended, or explicitly state the <100 ppm restriction in the question. | G59: NS5-030.png | H59: Thomas_GeoQueryBench_New_Query_Error_Report(1).xlsx

Sheet All Query Reviews
